Workbook

Sheet Mode d'emploi
A1: Les réglages de Speed — où doit vivre chacun ?
A3: Relevé du 10 septembre 2026, pour la refonte : deux applications, l'atelier sur PC et la voiture.
A4: La question posée à chaque ligne est celle-ci et pas une autre : ce réglage doit-il rester accessible au volant ?
A6: Ce que tu remplis
A7: Onglet « Réglages », colonne F « Où » — les cellules jaunes, et elles seules.
A8: Trois valeurs dans la liste déroulante : Voiture, Atelier, À voir.
A9: La colonne G « Note » est libre : une précision, une condition, un « seulement si ».
A11: Exemple de ligne remplie
A12: Catégorie « Préférences d'appareil » · Réglage « Volume » · Où : Voiture · Note : « indispensable, ça dépend de l'autoradio »
A14: Ce qui est déjà pré-rempli
A15: Les huit réglages qui sont déjà sur l'écran de conduite aujourd'hui sont marqués « Voiture ».
A16: Change-les si tu n'es pas d'accord : rien n'est acquis.
... A23: L'onglet « Compte » totalise tes choix par catégorie, au fur et à mesure.

Sheet Réglages
A1: Catégorie | B1: Réglage | C1: Ce qu'il fait | D1: Aujourd'hui | E1: Portée | F1: Où | G1: Note
A2: Moteur | B2: Cylindres enregistrés | C2: Combien de cylindres avait le moteur enregistré ; ne change pas le son, sert à l'analyse d'un fichier | D2: Config › Moteur | E2: Profil | F2: Atelier
A3: Moteur | B3: Ralenti | C3: Régime à l'arrêt, débrayé — le son du feu rouge | D3: Config › Moteur | E3: Profil | F3: Atelier
A4: Moteur | B4: Régime de décollage | C4: Régime que l'embrayage impose dès que la voiture avance | D4: Config › Moteur | E4: Profil | F4: Atelier
A5: Moteur | B5: Seuil de coupure | C5: Régime auquel l'allumage commence à être coupé | D5: Config › Moteur | E5: Profil | F5: Atelier
A6: Moteur | B6: Rupteur | C6: Plafond absolu du régime | D6: Config › Moteur | E6: Profil | F6: Atelier
A7: Moteur | B7: Durée de coupure | C7: Durée d'une coupure au rupteur — c'est ce hachage qui crépite | D7: Config › Moteur | E7: Profil | F7: Atelier
A8: Moteur | B8: Inertie | C8: Poids du volant moteur : lourd, il met du temps à prendre ses tours | D8: Config › Moteur | E8: Profil | F8: Atelier
A9: Moteur | B9: Montée à vide | C9: Rapidité de montée quand les roues n'entraînent pas le moteur | D9: Config › Moteur | E9: Profil | F9: Atelier
A10: Moteur | B10: Frein moteur | C10: Rapidité avec laquelle le régime retombe pied levé | D10: Config › Moteur | E10: Profil | F10: Atelier
A11: Moteur | B11: Tremblement au ralenti | C11: Amplitude de l'oscillation d'un thermique ; ne va que dans le son | D11: Config › Moteur | E11: Profil | F11: Atelier
A12: Moteur | B12: Vitesse du tremblement | C12: Fréquence de ce tremblement | D12: Config › Moteur | E12: Profil | F12: Atelier
A13: Transmission | B13: Démultiplications | C13: La liste des rapports, du plus court au plus long | D13: Config › Transmission | E13: Profil | F13: Atelier | G13: peut-être inclure des profils "passage de vitesse" qui regroupent les paramètres correspondants - travaillés en atelier ? Ou intégrer ça dans les profils… je sais pas. Ou alors lier les paramètres de boite au moteur + le mode - sport ou route.
A14: Transmission | B14: Pont | C14: Démultiplication commune : la baisser fait tourner le moteur moins vite partout | D14: Config › Transmission | E14: Profil | F14: Atelier | G14: peut-être inclure des profils "passage de vitesse" qui regroupent les paramètres correspondants - travaillés en atelier ? Ou intégrer ça dans les profils… je sais pas. Ou alors lier les paramètres de boite au moteur + le mode - sport ou route.
A15: Transmission | B15: Rupteur atteint à | C15: Vitesse à laquelle le rupteur tombe en dernier rapport ; recalcule le pont | D15: Config › Transmission | E15: Profil | F15: Atelier | G15: peut-être inclure des profils "passage de vitesse" qui regroupent les paramètres correspondants - travaillés en atelier ? Ou intégrer ça dans les profils… je sais pas. Ou alors lier les paramètres de boite au moteur + le mode - sport ou route.
A16: Transmission | B16: Rayon de roue | C16: Une roue plus grande fait moins de tours pour la même vitesse | D16: Config › Transmission | E16: Profil | F16: Atelier | G16: peut-être inclure des profils "passage de vitesse" qui regroupent les paramètres correspondants - travaillés en atelier ? Ou intégrer ça dans les profils… je sais pas. Ou alors lier les paramètres de boite au moteur + le mode - sport ou route.
A17: Transmission | B17: Temps de passage | C17: Durée de toute la séquence : coupure, chute, coup de gaz, clac, reprise | D17: Config › Transmission | E17: Profil | F17: Atelier | G17: peut-être inclure des profils "passage de vitesse" qui regroupent les paramètres correspondants - travaillés en atelier ? Ou intégrer ça dans les profils… je sais pas. Ou alors lier les paramètres de boite au moteur + le mode - sport ou route.
A18: Transmission | B18: Passage 1→2, 2→3… | C18: Régime auquel chaque rapport cède la place, à charge moyenne (5 curseurs) | D18: Config › Transmission | E18: Profil | F18: Atelier | G18: peut-être inclure des profils "passage de vitesse" qui regroupent les paramètres correspondants - travaillés en atelier ? Ou intégrer ça dans les profils… je sais pas. Ou alors lier les paramètres de boite au moteur + le mode - sport ou route.
A19: Transmission | B19: Écart selon la charge | C19: De combien le passage recule pied au plancher et avance pied levé | D19: Config › Transmission | E19: Profil | F19: Atelier | G19: peut-être inclure des profils "passage de vitesse" qui regroupent les paramètres correspondants - travaillés en atelier ? Ou intégrer ça dans les profils… je sais pas. Ou alors lier les paramètres de boite au moteur + le mode - sport ou route.
A20: Transmission | B20: Dispersion aléatoire | C20: Tirage au sort à chaque passage, pour ne pas sonner comme une machine | D20: Config › Transmission | E20: Profil | F20: Atelier | G20: peut-être inclure des profils "passage de vitesse" qui regroupent les paramètres correspondants - travaillés en atelier ? Ou intégrer ça dans les profils… je sais pas. Ou alors lier les paramètres de boite au moteur + le mode - sport ou route.
A21: Transmission | B21: Première réservée au lancement | C21: La première n'est qu'une amorce, on n'y revient plus | D21: Config › Transmission | E21: Profil | F21: Voiture | G21: peut-être inclure des profils "passage de vitesse" qui regroupent les paramètres correspondants - travaillés en atelier ? Ou intégrer ça dans les profils… je sais pas. Ou alors lier les paramètres de boite au moteur + le mode - sport ou route.
A22: Transmission | B22: Passage en seconde à | C22: Vitesse au-delà de laquelle la première cède | D22: Config › Transmission | E22: Profil | F22: Atelier | G22: peut-être inclure des profils "passage de vitesse" qui regroupent les paramètres correspondants - travaillés en atelier ? Ou intégrer ça dans les profils… je sais pas. Ou alors lier les paramètres de boite au moteur + le mode - sport ou route.
A23: Transmission | B23: Ne jamais monter sous | C23: Plancher appliqué aux régimes de passage | D23: Config › Transmission | E23: Profil | F23: Atelier | G23: peut-être inclure des profils "passage de vitesse" qui regroupent les paramètres correspondants - travaillés en atelier ? Ou intégrer ça dans les profils… je sais pas. Ou alors lier les paramètres de boite au moteur + le mode - sport ou route.
A24: Transmission | B24: Descente sous | C24: Fraction du rupteur sous laquelle la boîte rétrograde | D24: Config › Transmission | E24: Profil | F24: Atelier | G24: peut-être inclure des profils "passage de vitesse" qui regroupent les paramètres correspondants - travaillés en atelier ? Ou intégrer ça dans les profils… je sais pas. Ou alors lier les paramètres de boite au moteur + le mode - sport ou route.
... A35: Signal de vitesse | B35: Décélération max retenue | C35: Le même plafond en freinage | D35: Config › Signal | E35: Profil | F35: Atelier | G35: tous les params "signal de vitesse" sont liés au profil de la voiture (la vraie) - donc valeurs par défaut en atelier, potentiellement adaptées avec le profil "voiture réelle" quand il est disponible (soit par choix du modèle de voiture dans un catalogue mis à disposition de l'utilisateur, soit par mesure dans l'onglet dédié à ça)
A36: Caractère et imperfections | B36: Rétrogradage forcé | C36: Descendre chercher le couple quand on enfonce, sans attendre le seuil | D36: Config › Caractère | E36: Profil | F36: Voiture
A37: Caractère et imperfections | B37: Déclenché au-delà de | C37: Charge à partir de laquelle la demande est jugée franche | D37: Config › Caractère | E37: Profil | F37: Atelier
A38: Caractère et imperfections | B38: Régime visé | C38: Régime cherché après la descente, en fraction du rupteur | D38: Config › Caractère | E38: Profil | F38: Atelier
A39: Caractère et imperfections | B39: Rapports descendus au plus | C39: Nombre maximal de rapports descendus d'un coup | D39: Config › Caractère | E39: Profil | F39: Voiture
A40: Caractère et imperfections | B40: Pétarade | C40: Claquements à l'échappement au lever de pied | D40: Config › Caractère | E40: Profil | F40: Voiture
A41: Caractère et imperfections | B41: À partir de | C41: Régime en deçà duquel aucun claquement | D41: Config › Caractère | E41: Profil | F41: Atelier
A42: Caractère et imperfections | B42: Intensité | C42: Volume des claquements | D42: Config › Caractère | E42: Profil | F42: Atelier
A43: Caractère et imperfections | B43: Claquements par salve | C43: Nombre de détonations à chaque lever de pied | D43: Config › Caractère | E43: Profil | F43: Atelier
A44: Caractère et imperfections | B44: À-coup de passage | C44: Le petit trou et la reprise pendant le changement | D44: Config › Caractère | E44: Profil | F44: Atelier
A45: Caractère et imperfections | B45: Profondeur | C45: Combien le niveau baisse pendant la coupure | D45: Config › Caractère | E45: Profil | F45: Atelier
A46: Caractère et imperfections | B46: Coupure de couple | C46: Combien le moteur passe en roue libre — c'est ce qui change le timbre | D46: Config › Caractère | E46: Profil | F46: Atelier
A47: Caractère et imperfections | B47: Plongée du régime | C47: De combien le moteur tombe sous le rapport visé pendant la coupure | D47: Config › Caractère | E47: Profil | F47: Atelier
... A77: Couches d'échantillons | B77: Lecture max | C77: Borne haute : au-dessus, il devient métallique | D77: Config › Couches | E77: Profil | F77: Atelier
A78: Origine du son et raccourcis | B78: Origine du son | C78: Enregistré, généré en direct, ou généré à l'avance | D78: Config › Profils | E78: Profil | F78: À voir | G78: tous les sons seront enregistrés sauf les effets - voir specs du nouveau modèle
A79: Origine du son et raccourcis | B79: Moteur | C79: Charge d'un coup un moteur entier de la bibliothèque (9 entrées) | D79: Conduite + Config | E79: Profil | F79: Atelier
...

Sheet Compte
A1: Ce que tu gardes au volant
A3: Catégorie | B3: Réglages | C3: Voiture | D3: Atelier | E3: À voir | F3: Reste à trancher
A4: Moteur | B4: =COUNTIF(Réglages!$A$2:$A$159,$A4) -> 11 | C4: =COUNTIFS(Réglages!$A$2:$A$159,$A4,Réglages!$F$2:$F$159,"Voiture") -> 0 | D4: =COUNTIFS(Réglages!$A$2:$A$159,$A4,Réglages!$F$2:$F$159,"Atelier") -> 11 | E4: =COUNTIFS(Réglages!$A$2:$A$159,$A4,Réglages!$F$2:$F$159,"À voir") -> 0 | F4: =$B4-$C4-$D4-$E4 -> 0
A5: Transmission | B5: =COUNTIF(Réglages!$A$2:$A$159,$A5) -> 17 | C5: =COUNTIFS(Réglages!$A$2:$A$159,$A5,Réglages!$F$2:$F$159,"Voiture") -> 1 | D5: =COUNTIFS(Réglages!$A$2:$A$159,$A5,Réglages!$F$2:$F$159,"Atelier") -> 16 | E5: =COUNTIFS(Réglages!$A$2:$A$159,$A5,Réglages!$F$2:$F$159,"À voir") -> 0 | F5: =$B5-$C5-$D5-$E5 -> 0
A6: Signal de vitesse | B6: =COUNTIF(Réglages!$A$2:$A$159,$A6) -> 6 | C6: =COUNTIFS(Réglages!$A$2:$A$159,$A6,Réglages!$F$2:$F$159,"Voiture") -> 0 | D6: =COUNTIFS(Réglages!$A$2:$A$159,$A6,Réglages!$F$2:$F$159,"Atelier") -> 6 | E6: =COUNTIFS(Réglages!$A$2:$A$159,$A6,Réglages!$F$2:$F$159,"À voir") -> 0 | F6: =$B6-$C6-$D6-$E6 -> 0
A7: Caractère et imperfections | B7: =COUNTIF(Réglages!$A$2:$A$159,$A7) -> 16 | C7: =COUNTIFS(Réglages!$A$2:$A$159,$A7,Réglages!$F$2:$F$159,"Voiture") -> 4 | D7: =COUNTIFS(Réglages!$A$2:$A$159,$A7,Réglages!$F$2:$F$159,"Atelier") -> 12 | E7: =COUNTIFS(Réglages!$A$2:$A$159,$A7,Réglages!$F$2:$F$159,"À voir") -> 0 | F7: =$B7-$C7-$D7-$E7 -> 0
A8: Mixage et niveaux | B8: =COUNTIF(Réglages!$A$2:$A$159,$A8) -> 16 | C8: =COUNTIFS(Réglages!$A$2:$A$159,$A8,Réglages!$F$2:$F$159,"Voiture") -> 0 | D8: =COUNTIFS(Réglages!$A$2:$A$159,$A8,Réglages!$F$2:$F$159,"Atelier") -> 16 | E8: =COUNTIFS(Réglages!$A$2:$A$159,$A8,Réglages!$F$2:$F$159,"À voir") -> 0 | F8: =$B8-$C8-$D8-$E8 -> 0
A9: Couches d'échantillons | B9: =COUNTIF(Réglages!$A$2:$A$159,$A9) -> 10 | C9: =COUNTIFS(Réglages!$A$2:$A$159,$A9,Réglages!$F$2:$F$159,"Voiture") -> 1 | D9: =COUNTIFS(Réglages!$A$2:$A$159,$A9,Réglages!$F$2:$F$159,"Atelier") -> 8 | E9: =COUNTIFS(Réglages!$A$2:$A$159,$A9,Réglages!$F$2:$F$159,"À voir") -> 1 | F9: =$B9-$C9-$D9-$E9 -> 0
A10: Origine du son et raccourcis | B10: =COUNTIF(Réglages!$A$2:$A$159,$A10) -> 4 | C10: =COUNTIFS(Réglages!$A$2:$A$159,$A10,Réglages!$F$2:$F$159,"Voiture") -> 0 | D10: =COUNTIFS(Réglages!$A$2:$A$159,$A10,Réglages!$F$2:$F$159,"Atelier") -> 3 | E10: =COUNTIFS(Réglages!$A$2:$A$159,$A10,Réglages!$F$2:$F$159,"À voir") -> 1 | F10: =$B10-$C10-$D10-$E10 -> 0
A11: Définition du moteur simulé | B11: =COUNTIF(Réglages!$A$2:$A$159,$A11) -> 28 | C11: =COUNTIFS(Réglages!$A$2:$A$159,$A11,Réglages!$F$2:$F$159,"Voiture") -> 0 | D11: =COUNTIFS(Réglages!$A$2:$A$159,$A11,Réglages!$F$2:$F$159,"Atelier") -> 28 | E11: =COUNTIFS(Réglages!$A$2:$A$159,$A11,Réglages!$F$2:$F$159,"À voir") -> 0 | F11: =$B11-$C11-$D11-$E11 -> 0
A12: Calcul et banc de synthèse | B12: =COUNTIF(Réglages!$A$2:$A$159,$A12) -> 12 | C12: =COUNTIFS(Réglages!$A$2:$A$159,$A12,Réglages!$F$2:$F$159,"Voiture") -> 0 | D12: =COUNTIFS(Réglages!$A$2:$A$159,$A12,Réglages!$F$2:$F$159,"Atelier") -> 0 | E12: =COUNTIFS(Réglages!$A$2:$A$159,$A12,Réglages!$F$2:$F$159,"À voir") -> 0 | F12: =$B12-$C12-$D12-$E12 -> 12
A13: Échappement et point d'écoute | B13: =COUNTIF(Réglages!$A$2:$A$159,$A13) -> 11 | C13: =COUNTIFS(Réglages!$A$2:$A$159,$A13,Réglages!$F$2:$F$159,"Voiture") -> 1 | D13: =COUNTIFS(Réglages!$A$2:$A$159,$A13,Réglages!$F$2:$F$159,"Atelier") -> 10 | E13: =COUNTIFS(Réglages!$A$2:$A$159,$A13,Réglages!$F$2:$F$159,"À voir") -> 0 | F13: =$B13-$C13-$D13-$E13 -> 0
A14: Étalonnage | B14: =COUNTIF(Réglages!$A$2:$A$159,$A14) -> 2 | C14: =COUNTIFS(Réglages!$A$2:$A$159,$A14,Réglages!$F$2:$F$159,"Voiture") -> 2 | D14: =COUNTIFS(Réglages!$A$2:$A$159,$A14,Réglages!$F$2:$F$159,"Atelier") -> 0 | E14: =COUNTIFS(Réglages!$A$2:$A$159,$A14,Réglages!$F$2:$F$159,"À voir") -> 0 | F14: =$B14-$C14-$D14-$E14 -> 0
A15: Préférences d'appareil | B15: =COUNTIF(Réglages!$A$2:$A$159,$A15) -> 12 | C15: =COUNTIFS(Réglages!$A$2:$A$159,$A15,Réglages!$F$2:$F$159,"Voiture") -> 7 | D15: =COUNTIFS(Réglages!$A$2:$A$159,$A15,Réglages!$F$2:$F$159,"Atelier") -> 0 | E15: =COUNTIFS(Réglages!$A$2:$A$159,$A15,Réglages!$F$2:$F$159,"À voir") -> 4 | F15: =$B15-$C15-$D15-$E15 -> 1
A16: Hors réseau et dépôt | B16: =COUNTIF(Réglages!$A$2:$A$159,$A16) -> 13 | C16: =COUNTIFS(Réglages!$A$2:$A$159,$A16,Réglages!$F$2:$F$159,"Voiture") -> 8 | D16: =COUNTIFS(Réglages!$A$2:$A$159,$A16,Réglages!$F$2:$F$159,"Atelier") -> 1 | E16: =COUNTIFS(Réglages!$A$2:$A$159,$A16,Réglages!$F$2:$F$159,"À voir") -> 4 | F16: =$B16-$C16-$D16-$E16 -> 0
A17: Total | B17: =SUM(B4:B16) -> 158 | C17: =SUM(C4:C16) -> 24 | D17: =SUM(D4:D16) -> 111 | E17: =SUM(E4:E16) -> 10 | F17: =SUM(F4:F16) -> 13
A19: Les nombres se recalculent à mesure que tu remplis la colonne « Où » de l'onglet Réglages.
